<?xml version="1.0"?>
<robot name="my_mobile">
  
  <!-- materials -->
  <material name="grey">
    <color rgba="0.6 0.6 0.6 1.0"/>
  </material>
  
  <material name="red">
    <color rgba="1 0 0 1.0"/>
  </material>
  
  <material name="black">
    <color rgba="0 0 0 1.0"/>
  </material>
  
  
  
  <!-- links -->
  <link name="chassis">
    
    <visual>
      <geometry>
        <box size="1.0 0.5 0.25"/>
      </geometry>
      <origin rpy="0 0 0" xyz="0 0 0"/>
      <material name="grey"/>
    </visual>
    
    <collision>
      <geometry>
        <box size="1.0 0.5 0.25"/>
      </geometry>
      <origin rpy="0 0 0" xyz="0 0 0"/>
    </collision>
    
    <inertial>
      <mass value="1.0"/>
      <inertia ixx="0.1" iyy="0.1" izz="0.1" ixy="0" ixz="0" iyz="0"/>
    </inertial>
    
  </link>
  
  
  <link name="caster">
    
    <visual>
      <geometry>
        <sphere radius="0.1"/>
      </geometry>
      <origin rpy="0 0 0" xyz="0 0 0"/>
      <material name="black"/>
    </visual>
    
    <collision>
      <geometry>
        <sphere radius="0.1"/>
      </geometry>
      <origin rpy="0 0 0" xyz="0 0 0"/>
      <surface>
        <friction>
          <ode>
            <mu>0</mu>
            <mu2>0</mu2>
            <slip1>1.0</slip1>
            <slip2>1.0</slip2>
          </ode>
        </friction>
      </surface>
    </collision>
    
    <inertial>
      <mass value="0.1"/>
      <inertia ixx="1e-5" iyy="1e-5" izz="1e-5" ixy="0" ixz="0" iyz="0"/>
    </inertial>
    
  </link>
  
  
  <link name="left_wheel">
    
    <visual>
      <geometry>
        <cylinder length="0.05" radius="0.1"/>
      </geometry>
      <origin rpy="0 0 0" xyz="0 0 0.025"/>
      <material name="red"/>
    </visual>
    
    <collision>
      <geometry>
        <cylinder length="0.05" radius="0.1"/>
      </geometry>
      <origin rpy="0 0 0" xyz="0 0 0.025"/>
      <surface>
        <friction>
          <ode>
            <mu>100000</mu>
            <mu2>100000</mu2>
          </ode>
        </friction>
      </surface>
    </collision>
    
    <inertial>
      <mass value="1.0"/>
      <inertia ixx="0.1" iyy="0.1" izz="0.1" ixy="0" ixz="0" iyz="0"/>
    </inertial>
    
  </link>
  
  
  <link name="right_wheel">
    
    <visual>
      <geometry>
        <cylinder length="0.05" radius="0.1"/>
      </geometry>
      <origin rpy="0 0 0" xyz="0 0 -0.025"/>
      <material name="red"/>
    </visual>
    
    <collision>
      <geometry>
        <cylinder length="0.05" radius="0.1"/>
      </geometry>
      <origin rpy="0 0 0" xyz="0 0 -0.025"/>
      <surface>
        <friction>
          <ode>
            <mu>100000</mu>
            <mu2>100000</mu2>
          </ode>
        </friction>
      </surface>
    </collision>
    
    <inertial>
      <mass value="1.0"/>
      <inertia ixx="0.1" iyy="0.1" izz="0.1" ixy="0" ixz="0" iyz="0"/>
    </inertial>
    
  </link>
  
  
  
  <!-- joints -->
  <joint name="caster_joint" type="fixed">
    <parent link="chassis"/>
    <child link="caster"/>
    <origin rpy="0 0 0" xyz="-0.3 0 -0.125"/>
  </joint>
  
  <joint name="left_wheel_joint" type="continuous">
    <parent link="chassis"/>
    <child link="left_wheel"/>
    <origin rpy="-1.57 0 0" xyz="0.3 0.25 -0.125"/>
    <axis xyz="0 0 1"/>
  </joint>
  
  <joint name="right_wheel_joint" type="continuous">
    <parent link="chassis"/>
    <child link="right_wheel"/>
    <origin rpy="-1.57 0 0" xyz="0.3 -0.25 -0.125"/>
    <axis xyz="0 0 1"/>
  </joint>
  
  
  
  <!-- transmissions -->
  <transmission name="left_wheel_trans">
    <type>transmission_interface/SimpleTransmission</type>
    <joint name="left_wheel_joint">
      <hardwareInterface>hardware_interface/EffortJointInterface</hardwareInterface>
    </joint>
    <actuator name="left_wheel_motor">
      <hardwareInterface>hardware_interface/EffortJointInterface</hardwareInterface>
      <mechanicalReduction>1</mechanicalReduction>
    </actuator>
  </transmission>
  
  <transmission name="right_wheel_trans">
    <type>transmission_interface/SimpleTransmission</type>
    <joint name="right_wheel_joint">
      <hardwareInterface>hardware_interface/EffortJointInterface</hardwareInterface>
    </joint>
    <actuator name="right_wheel_motor">
      <hardwareInterface>hardware_interface/EffortJointInterface</hardwareInterface>
      <mechanicalReduction>1</mechanicalReduction>
    </actuator>
  </transmission>
  
  
  
  <!-- gazebo properties -->
  <gazebo reference="chassis">
    <material>Gazebo/Gray</material>
  </gazebo>
  
  <gazebo reference="caster">
    <material>Gazebo/Black</material>
  </gazebo>
  
  <gazebo reference="left_wheel">
    <material>Gazebo/Red</material>
  </gazebo>
  
  <gazebo reference="right_wheel">
    <material>Gazebo/Red</material>
  </gazebo>
  
  <gazebo>
    <plugin filename="libgazebo_ros_diff_drive.so" name="differential_drive_controller">
      <alwaysOn>true</alwaysOn>
      <updateRate>20</updateRate>
      <leftJoint>left_wheel_joint</leftJoint>
      <rightJoint>right_wheel_joint</rightJoint>
      <wheelSeparation>0.5</wheelSeparation>
      <wheelDiameter>0.2</wheelDiameter>
      <wheelTorque>1</wheelTorque>
      <commandTopic>cmd_vel</commandTopic>
      <odometryTopic>odom</odometryTopic>
      <odometryFrame>odom</odometryFrame>
      <robotBaseFrame>chassis</robotBaseFrame>
    </plugin>
  </gazebo>
  
</robot>
